[2023-12-07T22:37:48.769+0000] {taskinstance.py:1159} INFO - Dependencies all met for dep_context=non-requeueable deps ti=<TaskInstance: weather_dag.transform_load_weather_data manual__2023-12-07T22:35:35.255904+00:00 [queued]>
[2023-12-07T22:37:48.776+0000] {taskinstance.py:1159} INFO - Dependencies all met for dep_context=requeueable deps ti=<TaskInstance: weather_dag.transform_load_weather_data manual__2023-12-07T22:35:35.255904+00:00 [queued]>
[2023-12-07T22:37:48.776+0000] {taskinstance.py:1361} INFO - Starting attempt 2 of 3
[2023-12-07T22:37:48.797+0000] {taskinstance.py:1382} INFO - Executing <Task(PythonOperator): transform_load_weather_data> on 2023-12-07 22:35:35.255904+00:00
[2023-12-07T22:37:48.801+0000] {standard_task_runner.py:57} INFO - Started process 35461 to run task
[2023-12-07T22:37:48.808+0000] {standard_task_runner.py:84} INFO - Running: ['airflow', 'tasks', 'run', 'weather_dag', 'transform_load_weather_data', 'manual__2023-12-07T22:35:35.255904+00:00', '--job-id', '41', '--raw', '--subdir', 'DAGS_FOLDER/weather_dag.py', '--cfg-path', '/tmp/tmpj1v29fys']
[2023-12-07T22:37:48.809+0000] {standard_task_runner.py:85} INFO - Job 41: Subtask transform_load_weather_data
[2023-12-07T22:37:48.847+0000] {task_command.py:416} INFO - Running <TaskInstance: weather_dag.transform_load_weather_data manual__2023-12-07T22:35:35.255904+00:00 [running]> on host ip-172-31-85-231.ec2.internal
[2023-12-07T22:37:48.904+0000] {taskinstance.py:1662} INFO - Exporting env vars: AIRFLOW_CTX_DAG_EMAIL='sam@example.com' AIRFLOW_CTX_DAG_OWNER='airflow' AIRFLOW_CTX_DAG_ID='weather_dag' AIRFLOW_CTX_TASK_ID='transform_load_weather_data' AIRFLOW_CTX_EXECUTION_DATE='2023-12-07T22:35:35.255904+00:00' AIRFLOW_CTX_TRY_NUMBER='2' AIRFLOW_CTX_DAG_RUN_ID='manual__2023-12-07T22:35:35.255904+00:00'
[2023-12-07T22:37:48.916+0000] {taskinstance.py:1937} ERROR - Task failed with exception
Traceback (most recent call last):
  File "/usr/local/lib/python3.10/dist-packages/airflow/operators/python.py", line 192, in execute
    return_value = self.execute_callable()
  File "/usr/local/lib/python3.10/dist-packages/airflow/operators/python.py", line 209, in execute_callable
    return self.python_callable(*self.op_args, **self.op_kwargs)
  File "/home/ubuntu/airflow/dags/weather_dag.py", line 51, in transform_load_data
    df_data.to_csv(f"{dt_string}.csv", index=False)
  File "/usr/local/lib/python3.10/dist-packages/pandas/core/generic.py", line 3902, in to_csv
    return DataFrameRenderer(formatter).to_csv(
  File "/usr/local/lib/python3.10/dist-packages/pandas/io/formats/format.py", line 1152, in to_csv
    csv_formatter.save()
  File "/usr/local/lib/python3.10/dist-packages/pandas/io/formats/csvs.py", line 247, in save
    with get_handle(
  File "/usr/local/lib/python3.10/dist-packages/pandas/io/common.py", line 739, in get_handle
    check_parent_directory(str(handle))
  File "/usr/local/lib/python3.10/dist-packages/pandas/io/common.py", line 604, in check_parent_directory
    raise OSError(rf"Cannot save file into a non-existent directory: '{parent}'")
OSError: Cannot save file into a non-existent directory: 'Current Weather in Manchester is: 07/12'
[2023-12-07T22:37:48.922+0000] {taskinstance.py:1400} INFO - Marking task as UP_FOR_RETRY. dag_id=weather_dag, task_id=transform_load_weather_data, execution_date=20231207T223535, start_date=20231207T223748, end_date=20231207T223748
[2023-12-07T22:37:48.942+0000] {standard_task_runner.py:104} ERROR - Failed to execute job 41 for task transform_load_weather_data (Cannot save file into a non-existent directory: 'Current Weather in Manchester is: 07/12'; 35461)
[2023-12-07T22:37:48.981+0000] {local_task_job_runner.py:228} INFO - Task exited with return code 1
[2023-12-07T22:37:48.994+0000] {taskinstance.py:2778} INFO - 0 downstream tasks scheduled from follow-on schedule check
