[2023-12-08T10:23:02.177+0000] {taskinstance.py:1159} INFO - Dependencies all met for dep_context=non-requeueable deps ti=<TaskInstance: weather_dag.is_weather_api_ready manual__2023-12-08T10:22:58.101936+00:00 [queued]>
[2023-12-08T10:23:02.184+0000] {taskinstance.py:1159} INFO - Dependencies all met for dep_context=requeueable deps ti=<TaskInstance: weather_dag.is_weather_api_ready manual__2023-12-08T10:22:58.101936+00:00 [queued]>
[2023-12-08T10:23:02.185+0000] {taskinstance.py:1361} INFO - Starting attempt 1 of 3
[2023-12-08T10:23:02.205+0000] {taskinstance.py:1382} INFO - Executing <Task(HttpSensor): is_weather_api_ready> on 2023-12-08 10:22:58.101936+00:00
[2023-12-08T10:23:02.209+0000] {standard_task_runner.py:57} INFO - Started process 5903 to run task
[2023-12-08T10:23:02.216+0000] {standard_task_runner.py:84} INFO - Running: ['airflow', 'tasks', 'run', 'weather_dag', 'is_weather_api_ready', 'manual__2023-12-08T10:22:58.101936+00:00', '--job-id', '62', '--raw', '--subdir', 'DAGS_FOLDER/weather_dag.py', '--cfg-path', '/tmp/tmpp1_gz8sc']
[2023-12-08T10:23:02.217+0000] {standard_task_runner.py:85} INFO - Job 62: Subtask is_weather_api_ready
[2023-12-08T10:23:02.265+0000] {task_command.py:416} INFO - Running <TaskInstance: weather_dag.is_weather_api_ready manual__2023-12-08T10:22:58.101936+00:00 [running]> on host ip-172-31-85-231.ec2.internal
[2023-12-08T10:23:02.331+0000] {taskinstance.py:1662} INFO - Exporting env vars: AIRFLOW_CTX_DAG_EMAIL='sam@example.com' AIRFLOW_CTX_DAG_OWNER='airflow' AIRFLOW_CTX_DAG_ID='weather_dag' AIRFLOW_CTX_TASK_ID='is_weather_api_ready' AIRFLOW_CTX_EXECUTION_DATE='2023-12-08T10:22:58.101936+00:00' AIRFLOW_CTX_TRY_NUMBER='1' AIRFLOW_CTX_DAG_RUN_ID='manual__2023-12-08T10:22:58.101936+00:00'
[2023-12-08T10:23:02.332+0000] {http.py:130} INFO - Poking: /data/2.5/weather?q=manchester&appid={api_key}
[2023-12-08T10:23:02.338+0000] {base.py:73} INFO - Using connection ID 'weathermap_api' for task execution.
[2023-12-08T10:23:02.583+0000] {http.py:178} ERROR - HTTP error: Unauthorized
[2023-12-08T10:23:02.584+0000] {http.py:179} ERROR - {"cod":401, "message": "Invalid API key. Please see https://openweathermap.org/faq#error401 for more info."}
[2023-12-08T10:23:02.589+0000] {taskinstance.py:1937} ERROR - Task failed with exception
Traceback (most recent call last):
  File "/usr/local/lib/python3.10/dist-packages/airflow/providers/http/hooks/http.py", line 176, in check_response
    response.raise_for_status()
  File "/usr/local/lib/python3.10/dist-packages/requests/models.py", line 1021, in raise_for_status
    raise HTTPError(http_error_msg, response=self)
requests.exceptions.HTTPError: 401 Client Error: Unauthorized for url: https://api.openweathermap.org/data/2.5/weather?q=manchester&appid=%7Bapi_key%7D

During handling of the above exception, another exception occurred:

Traceback (most recent call last):
  File "/usr/local/lib/python3.10/dist-packages/airflow/sensors/base.py", line 257, in execute
    raise e
  File "/usr/local/lib/python3.10/dist-packages/airflow/sensors/base.py", line 239, in execute
    poke_return = self.poke(context)
  File "/usr/local/lib/python3.10/dist-packages/airflow/providers/http/sensors/http.py", line 148, in poke
    raise exc
  File "/usr/local/lib/python3.10/dist-packages/airflow/providers/http/sensors/http.py", line 132, in poke
    response = hook.run(
  File "/usr/local/lib/python3.10/dist-packages/airflow/providers/http/hooks/http.py", line 166, in run
    return self.run_and_check(session, prepped_request, extra_options)
  File "/usr/local/lib/python3.10/dist-packages/airflow/providers/http/hooks/http.py", line 217, in run_and_check
    self.check_response(response)
  File "/usr/local/lib/python3.10/dist-packages/airflow/providers/http/hooks/http.py", line 180, in check_response
    raise AirflowException(str(response.status_code) + ":" + response.reason)
airflow.exceptions.AirflowException: 401:Unauthorized
[2023-12-08T10:23:02.604+0000] {taskinstance.py:1400} INFO - Marking task as UP_FOR_RETRY. dag_id=weather_dag, task_id=is_weather_api_ready, execution_date=20231208T102258, start_date=20231208T102302, end_date=20231208T102302
[2023-12-08T10:23:02.642+0000] {standard_task_runner.py:104} ERROR - Failed to execute job 62 for task is_weather_api_ready (401:Unauthorized; 5903)
[2023-12-08T10:23:02.667+0000] {local_task_job_runner.py:228} INFO - Task exited with return code 1
[2023-12-08T10:23:02.687+0000] {taskinstance.py:2778} INFO - 0 downstream tasks scheduled from follow-on schedule check
