[2023-12-07T22:14:52.139+0000] {taskinstance.py:1159} INFO - Dependencies all met for dep_context=non-requeueable deps ti=<TaskInstance: weather_dag.transform_load_weather_data manual__2023-12-07T22:12:38.078314+00:00 [queued]>
[2023-12-07T22:14:52.147+0000] {taskinstance.py:1159} INFO - Dependencies all met for dep_context=requeueable deps ti=<TaskInstance: weather_dag.transform_load_weather_data manual__2023-12-07T22:12:38.078314+00:00 [queued]>
[2023-12-07T22:14:52.147+0000] {taskinstance.py:1361} INFO - Starting attempt 2 of 3
[2023-12-07T22:14:52.172+0000] {taskinstance.py:1382} INFO - Executing <Task(PythonOperator): transform_load_weather_data> on 2023-12-07 22:12:38.078314+00:00
[2023-12-07T22:14:52.176+0000] {standard_task_runner.py:57} INFO - Started process 33349 to run task
[2023-12-07T22:14:52.183+0000] {standard_task_runner.py:84} INFO - Running: ['airflow', 'tasks', 'run', 'weather_dag', 'transform_load_weather_data', 'manual__2023-12-07T22:12:38.078314+00:00', '--job-id', '24', '--raw', '--subdir', 'DAGS_FOLDER/weather_dag.py', '--cfg-path', '/tmp/tmpsn6n75my']
[2023-12-07T22:14:52.184+0000] {standard_task_runner.py:85} INFO - Job 24: Subtask transform_load_weather_data
[2023-12-07T22:14:52.220+0000] {task_command.py:416} INFO - Running <TaskInstance: weather_dag.transform_load_weather_data manual__2023-12-07T22:12:38.078314+00:00 [running]> on host ip-172-31-85-231.ec2.internal
[2023-12-07T22:14:52.277+0000] {taskinstance.py:1662} INFO - Exporting env vars: AIRFLOW_CTX_DAG_EMAIL='sam@example.com' AIRFLOW_CTX_DAG_OWNER='airflow' AIRFLOW_CTX_DAG_ID='weather_dag' AIRFLOW_CTX_TASK_ID='transform_load_weather_data' AIRFLOW_CTX_EXECUTION_DATE='2023-12-07T22:12:38.078314+00:00' AIRFLOW_CTX_TRY_NUMBER='2' AIRFLOW_CTX_DAG_RUN_ID='manual__2023-12-07T22:12:38.078314+00:00'
[2023-12-07T22:14:52.278+0000] {taskinstance.py:1937} ERROR - Task failed with exception
Traceback (most recent call last):
  File "/usr/local/lib/python3.10/dist-packages/airflow/operators/python.py", line 192, in execute
    return_value = self.execute_callable()
  File "/usr/local/lib/python3.10/dist-packages/airflow/operators/python.py", line 209, in execute_callable
    return self.python_callable(*self.op_args, **self.op_kwargs)
  File "/home/ubuntu/airflow/dags/weather_dag.py", line 17, in transform_load_data
    data = task_instance.xcom_pull(task_id="extract_weather_data")
  File "/usr/local/lib/python3.10/dist-packages/airflow/utils/session.py", line 79, in wrapper
    return func(*args, session=session, **kwargs)
TypeError: TaskInstance.xcom_pull() got an unexpected keyword argument 'task_id'
[2023-12-07T22:14:52.282+0000] {taskinstance.py:1400} INFO - Marking task as UP_FOR_RETRY. dag_id=weather_dag, task_id=transform_load_weather_data, execution_date=20231207T221238, start_date=20231207T221452, end_date=20231207T221452
[2023-12-07T22:14:52.298+0000] {standard_task_runner.py:104} ERROR - Failed to execute job 24 for task transform_load_weather_data (TaskInstance.xcom_pull() got an unexpected keyword argument 'task_id'; 33349)
[2023-12-07T22:14:52.314+0000] {local_task_job_runner.py:228} INFO - Task exited with return code 1
[2023-12-07T22:14:52.326+0000] {taskinstance.py:2778} INFO - 0 downstream tasks scheduled from follow-on schedule check
